[2023-03-26 12:49:00,728] root - INFO - Training pipleine config: TrainingPipelineConfig(artifact_dir='E:\\Data science\\Projects\\project_ml\\visa\\artifact')
[2023-03-26 12:49:00,728] root - ERROR - 
        Error occured in script: 
        [ E:\Data science\Projects\project_ml\visa\pipeline\pipeline.py ] at 
        try block line number: [43] and exception block line number: [47] 
        error message: [
        Error occured in script: 
        [ E:\Data science\Projects\project_ml\visa\pipeline\pipeline.py ] at 
        try block line number: [33] and exception block line number: [36] 
        error message: [
        Error occured in script: 
        [ E:\Data science\Projects\project_ml\visa\config\configuration.py ] at 
        try block line number: [33] and exception block line number: [61] 
        error message: ['dataset_download_url']
        ]
        ]
        
